/usr/bin/python3: can't open file '/home/pi4/Desktop/phip/command/receive.py': [Errno 2] No such file or directory
/usr/bin/python3: can't open file '/home/pi4/Desktop/phip/command/receive.py': [Errno 2] No such file or directory
/usr/bin/python3: can't open file '/home/pi4/Desktop/phip/command/receive.py': [Errno 2] No such file or directory
/usr/bin/python3: can't open file '/home/pi4/Desktop/phip/command/receive.py': [Errno 2] No such file or directory
/usr/bin/python3: can't open file '/home/pi4/Desktop/phip/command/receive.py': [Errno 2] No such file or directory
/usr/bin/python3: can't open file '/home/pi4/Desktop/phip/command/receive.py': [Errno 2] No such file or directory
/usr/bin/python3: can't open file '/home/pi4/Desktop/phip/command/receive.py': [Errno 2] No such file or directory
/usr/bin/python3: can't open file '/home/pi4/Desktop/phip/command/receive.py': [Errno 2] No such file or directory
/usr/bin/python3: can't open file '/home/pi4/Desktop/phip/command/receive.py': [Errno 2] No such file or directory
/usr/bin/python3: can't open file '/home/pi4/Desktop/phip/command/receive.py': [Errno 2] No such file or directory
/usr/bin/python3: can't open file '/home/pi4/Desktop/phip/command/receive.py': [Errno 2] No such file or directory
/usr/bin/python3: can't open file '/home/pi4/Desktop/phip/command/receive.py': [Errno 2] No such file or directory
/usr/bin/python3: can't open file '/home/pi4/Desktop/phip/command/receive.py': [Errno 2] No such file or directory
/usr/bin/python3: can't open file '/home/pi4/Desktop/phip/command/receive.py': [Errno 2] No such file or directory
/usr/bin/python3: can't open file '/home/pi4/Desktop/phip/command/receive.py': [Errno 2] No such file or directory
/usr/bin/python3: can't open file '/home/pi4/Desktop/phip/command/receive.py': [Errno 2] No such file or directory
/usr/bin/python3: can't open file '/home/pi4/Desktop/phip/command/receive.py': [Errno 2] No such file or directory
/usr/bin/python3: can't open file '/home/pi4/Desktop/phip/command/receive.py': [Errno 2] No such file or directory
/usr/bin/python3: can't open file '/home/pi4/Desktop/phip/command/receive.py': [Errno 2] No such file or directory
/usr/bin/python3: can't open file '/home/pi4/Desktop/phip/command/receive.py': [Errno 2] No such file or directory
/usr/bin/python3: can't open file '/home/pi4/Desktop/phip/command/receive.py': [Errno 2] No such file or directory
/usr/bin/python3: can't open file '/home/pi4/Desktop/phip/command/receive.py': [Errno 2] No such file or directory
/usr/bin/python3: can't open file '/home/pi4/Desktop/phip/command/receive.py': [Errno 2] No such file or directory
/usr/bin/python3: can't open file '/home/pi4/Desktop/phip/command/receive.py': [Errno 2] No such file or directory
/usr/bin/python3: can't open file '/home/pi4/Desktop/phip/command/receive.py': [Errno 2] No such file or directory
/usr/bin/python3: can't open file '/home/pi4/Desktop/phip/command/receive.py': [Errno 2] No such file or directory
/usr/bin/python3: can't open file '/home/pi4/Desktop/phip/command/receive.py': [Errno 2] No such file or directory
/usr/bin/python3: can't open file '/home/pi4/Desktop/phip/command/receive.py': [Errno 2] No such file or directory
/usr/bin/python3: can't open file '/home/pi4/Desktop/phip/command/receive.py': [Errno 2] No such file or directory
Traceback (most recent call last):
  File "/home/pi4/Desktop/phip/command/receive.py", line 7, in <module>
    from send import send_attribute_to_coreiot
ModuleNotFoundError: No module named 'send'
Traceback (most recent call last):
  File "/home/pi4/Desktop/phip/command/receive.py", line 7, in <module>
    from send import send_attribute_to_coreiot
ModuleNotFoundError: No module named 'send'
Traceback (most recent call last):
  File "/home/pi4/Desktop/phip/command/receive.py", line 7, in <module>
    from send import send_attribute_to_coreiot
ModuleNotFoundError: No module named 'send'
Traceback (most recent call last):
  File "/home/pi4/Desktop/phip/command/receive.py", line 7, in <module>
    from send import send_attribute_to_coreiot
ModuleNotFoundError: No module named 'send'
Traceback (most recent call last):
  File "/home/pi4/Desktop/phip/command/receive.py", line 7, in <module>
    from send import send_attribute_to_coreiot
ModuleNotFoundError: No module named 'send'
Traceback (most recent call last):
  File "/home/pi4/Desktop/phip/command/receive.py", line 7, in <module>
    from send import send_attribute_to_coreiot
ModuleNotFoundError: No module named 'send'
Traceback (most recent call last):
  File "/home/pi4/Desktop/phip/command/receive.py", line 7, in <module>
    from send import send_attribute_to_coreiot
ModuleNotFoundError: No module named 'send'
Traceback (most recent call last):
  File "/home/pi4/Desktop/phip/command/receive.py", line 7, in <module>
    from send import send_attribute_to_coreiot
ModuleNotFoundError: No module named 'send'
Traceback (most recent call last):
  File "/home/pi4/Desktop/phip/command/receive.py", line 7, in <module>
    from send import send_attribute_to_coreiot
ModuleNotFoundError: No module named 'send'
Traceback (most recent call last):
  File "/home/pi4/Desktop/phip/command/receive.py", line 7, in <module>
    from send import send_attribute_to_coreiot
ModuleNotFoundError: No module named 'send'
Traceback (most recent call last):
  File "/home/pi4/Desktop/phip/command/receive.py", line 7, in <module>
    from send import send_attribute_to_coreiot
ModuleNotFoundError: No module named 'send'
Traceback (most recent call last):
  File "/home/pi4/Desktop/phip/command/receive.py", line 7, in <module>
    from send import send_attribute_to_coreiot
ModuleNotFoundError: No module named 'send'
Traceback (most recent call last):
  File "/home/pi4/Desktop/phip/command/receive.py", line 7, in <module>
    from send import send_attribute_to_coreiot
ModuleNotFoundError: No module named 'send'
Traceback (most recent call last):
  File "/home/pi4/Desktop/phip/command/receive.py", line 7, in <module>
    from send import send_attribute_to_coreiot
ModuleNotFoundError: No module named 'send'
Traceback (most recent call last):
  File "/home/pi4/Desktop/phip/command/receive.py", line 7, in <module>
    from send import send_attribute_to_coreiot
ModuleNotFoundError: No module named 'send'
Traceback (most recent call last):
  File "/home/pi4/Desktop/phip/command/receive.py", line 7, in <module>
    from send import send_attribute_to_coreiot
ModuleNotFoundError: No module named 'send'
Traceback (most recent call last):
  File "/home/pi4/Desktop/phip/command/receive.py", line 7, in <module>
    from send import send_attribute_to_coreiot
ModuleNotFoundError: No module named 'send'
Traceback (most recent call last):
  File "/home/pi4/Desktop/phip/command/receive.py", line 7, in <module>
    from send import send_attribute_to_coreiot
ModuleNotFoundError: No module named 'send'
Traceback (most recent call last):
  File "/home/pi4/Desktop/phip/command/receive.py", line 7, in <module>
    from send import send_attribute_to_coreiot
ModuleNotFoundError: No module named 'send'
Traceback (most recent call last):
  File "/home/pi4/Desktop/phip/command/receive.py", line 7, in <module>
    from send import send_attribute_to_coreiot
ModuleNotFoundError: No module named 'send'
Traceback (most recent call last):
  File "/home/pi4/Desktop/phip/command/receive.py", line 7, in <module>
    from send import send_attribute_to_coreiot
ModuleNotFoundError: No module named 'send'
Traceback (most recent call last):
  File "/home/pi4/Desktop/phip/command/receive.py", line 7, in <module>
    from send import send_attribute_to_coreiot
ModuleNotFoundError: No module named 'send'
Traceback (most recent call last):
  File "/home/pi4/Desktop/phip/command/receive.py", line 7, in <module>
    from send import send_attribute_to_coreiot
ModuleNotFoundError: No module named 'send'
Traceback (most recent call last):
  File "/home/pi4/Desktop/phip/command/receive.py", line 7, in <module>
    from send import send_attribute_to_coreiot
ModuleNotFoundError: No module named 'send'
Traceback (most recent call last):
  File "/home/pi4/Desktop/phip/command/receive.py", line 7, in <module>
    from send import send_attribute_to_coreiot
ModuleNotFoundError: No module named 'send'
Traceback (most recent call last):
  File "/home/pi4/Desktop/phip/command/receive.py", line 7, in <module>
    from send import send_attribute_to_coreiot
ModuleNotFoundError: No module named 'send'
Traceback (most recent call last):
  File "/home/pi4/Desktop/phip/command/receive.py", line 7, in <module>
    from send import send_attribute_to_coreiot
ModuleNotFoundError: No module named 'send'
Traceback (most recent call last):
  File "/home/pi4/Desktop/phip/command/receive.py", line 7, in <module>
    from send import send_attribute_to_coreiot
ModuleNotFoundError: No module named 'send'
Traceback (most recent call last):
  File "/home/pi4/Desktop/phip/command/receive.py", line 7, in <module>
    from send import send_attribute_to_coreiot
ModuleNotFoundError: No module named 'send'
Traceback (most recent call last):
  File "/home/pi4/Desktop/phip/command/receive.py", line 7, in <module>
    from send import send_attribute_to_coreiot
ModuleNotFoundError: No module named 'send'
Traceback (most recent call last):
  File "/home/pi4/Desktop/phip/command/receive.py", line 7, in <module>
    from send import send_attribute_to_coreiot
ModuleNotFoundError: No module named 'send'
Traceback (most recent call last):
  File "/home/pi4/Desktop/phip/command/receive.py", line 7, in <module>
    from send import send_attribute_to_coreiot
ModuleNotFoundError: No module named 'send'
Traceback (most recent call last):
  File "/home/pi4/Desktop/phip/command/receive.py", line 7, in <module>
    from send import send_attribute_to_coreiot
ModuleNotFoundError: No module named 'send'
Traceback (most recent call last):
  File "/home/pi4/Desktop/phip/command/receive.py", line 7, in <module>
    from send import send_attribute_to_coreiot
ModuleNotFoundError: No module named 'send'
Traceback (most recent call last):
  File "/home/pi4/Desktop/phip/command/receive.py", line 7, in <module>
    from send import send_attribute_to_coreiot
ModuleNotFoundError: No module named 'send'
Traceback (most recent call last):
  File "/home/pi4/Desktop/phip/command/receive.py", line 7, in <module>
    from send import send_attribute_to_coreiot
ModuleNotFoundError: No module named 'send'
Traceback (most recent call last):
  File "/home/pi4/Desktop/phip/command/receive.py", line 7, in <module>
    from send import send_attribute_to_coreiot
ModuleNotFoundError: No module named 'send'
Traceback (most recent call last):
  File "/home/pi4/Desktop/phip/command/receive.py", line 7, in <module>
    from send import send_attribute_to_coreiot
ModuleNotFoundError: No module named 'send'
Traceback (most recent call last):
  File "/home/pi4/Desktop/phip/command/receive.py", line 7, in <module>
    from send import send_attribute_to_coreiot
ModuleNotFoundError: No module named 'send'
Traceback (most recent call last):
  File "/home/pi4/Desktop/phip/command/receive.py", line 7, in <module>
    from send import send_attribute_to_coreiot
ModuleNotFoundError: No module named 'send'
Traceback (most recent call last):
  File "/home/pi4/Desktop/phip/command/receive.py", line 7, in <module>
    from send import send_attribute_to_coreiot
ModuleNotFoundError: No module named 'send'
